Workbook
Name Slicer_Gender: #N/A
Name Slicer_Generation: #N/A
Name Slicer_Product_Category: #N/A

Sheet Q1 Sales by Product Category
A3: Product Category | B3: Sum of Sales
A4: Beauty | B4: 143515
A5: Clothing | B5: 155580
A6: Electronics | B6: 156905
A7: Grand Total | B7: 456000

Sheet Q2 Sales by Category and Gender
A3: Sum of Sales | B3: Gender
A4: Product Category | B4: Female | C4: Male | D4: Grand Total
A5: Beauty | B5: 0.16410088 | C5: 0.150625 | D5: 0.31472588
A6: Clothing | B6: 0.17823465 | C6: 0.16294956 | D6: 0.34118421
A7: Electronics | B7: 0.16827851 | C7: 0.1758114 | D7: 0.34408991
A8: Grand Total | B8: 0.51061404 | C8: 0.48938596 | D8: 1

Sheet Sheet1
A3: Sum of Sales | B3: Generation
A4: Product Category | B4: Adult | C4: Senior | D4: Young Adult | E4: Grand Total
A5: Beauty | B5: 0.1491886 | C5: 0.074747807 | D5: 0.090789474 | E5: 0.31472588
A6: Clothing | B6: 0.13675439 | C6: 0.10322368 | D6: 0.10120614 | E6: 0.34118421
A7: Electronics | B7: 0.13004386 | C7: 0.13596491 | D7: 0.07808114 | E7: 0.34408991
A8: Grand Total | B8: 0.41598684 | C8: 0.3139364 | D8: 0.27007675 | E8: 1

Sheet retail_sales_dataset
A1: Transaction ID | B1: Day | C1: Month | D1: Year | E1: Date | F1: Customer ID | G1: Gender | H1: Age | I1: Generation | J1: Product Category | K1: Quantity | L1: Price per Unit | M1: Sales | N1: Commission 2023 | O1: Commission 2024 | P1: Commission Total
A2: 1 | B2: =VLOOKUP(A2,retail_sales_dataset!$1:$1048576, 13, FALSE) -> 150 | C2: =MONTH(E2) -> 11 | D2: =YEAR(E2) -> 2023 | E2: 45254 | F2: CUST001 | G2: Male | H2: 34 | I2: {=_xlfn.IFS(H2<30, "Young Adult", H2<50, "Adult", H2>=50, "Senior")} -> Adult | J2: Beauty | K2: 3 | L2: 50 | M2: =K2 * L2 -> 150 | N2: =M2 * $Q$3 -> 2.25 | O2: =M2 * $Q$4 -> 3 | Q2: rate %
A3: 2 | B3: =DAY(E3) -> 27 | C3: =MONTH(E3) -> 2 | D3: =YEAR(E3) -> 2023 | E3: 44984 | F3: CUST002 | G3: Female | H3: 26 | I3: {=_xlfn.IFS(H3<30, "Young Adult", H3<50, "Adult", H3>=50, "Senior")} -> Young Adult | J3: Clothing | K3: 2 | L3: 500 | M3: =K3 * L3 -> 1000 | N3: =M3 * $Q$3 -> 15 | O3: =M3 * $Q$4 -> 20 | P3: commission 2023 | Q3: 0.015
A4: 3 | B4: =DAY(E4) -> 13 | C4: =MONTH(E4) -> 1 | D4: =YEAR(E4) -> 2023 | E4: 44939 | F4: CUST003 | G4: Male | H4: 50 | I4: {=_xlfn.IFS(H4<30, "Young Adult", H4<50, "Adult", H4>=50, "Senior")} -> Senior | J4: Electronics | K4: 1 | L4: 30 | M4: =K4 * L4 -> 30 | N4: =M4 * $Q$3 -> 0.45 | O4: =M4 * $Q$4 -> 0.6 | P4: commission 2024 | Q4: 0.02
A5: 4 | B5: =DAY(E5) -> 21 | C5: =MONTH(E5) -> 5 | D5: =YEAR(E5) -> 2023 | E5: 45067 | F5: CUST004 | G5: Male | H5: 37 | I5: {=_xlfn.IFS(H5<30, "Young Adult", H5<50, "Adult", H5>=50, "Senior")} -> Adult | J5: Clothing | K5: 1 | L5: 500 | M5: =K5 * L5 -> 500 | N5: =M5 * $Q$3 -> 7.5 | O5: =M5 * $Q$4 -> 10
A6: 5 | B6: =DAY(E6) -> 6 | C6: =MONTH(E6) -> 5 | D6: =YEAR(E6) -> 2023 | E6: 45052 | F6: CUST005 | G6: Male | H6: 30 | I6: {=_xlfn.IFS(H6<30, "Young Adult", H6<50, "Adult", H6>=50, "Senior")} -> Adult | J6: Beauty | K6: 2 | L6: 50 | M6: =K6 * L6 -> 100 | N6: =M6 * $Q$3 -> 1.5 | O6: =M6 * $Q$4 -> 2
A7: 6 | B7: =DAY(E7) -> 25 | C7: =MONTH(E7) -> 4 | D7: =YEAR(E7) -> 2023 | E7: 45041 | F7: CUST006 | G7: Female | H7: 45 | I7: {=_xlfn.IFS(H7<30, "Young Adult", H7<50, "Adult", H7>=50, "Senior")} -> Adult | J7: Beauty | K7: 1 | L7: 30 | M7: =K7 * L7 -> 30 | N7: =M7 * $Q$3 -> 0.45 | O7: =M7 * $Q$4 -> 0.6 | R7: Quantity
A8: 7 | B8: =DAY(E8) -> 13 | C8: =MONTH(E8) -> 3 | D8: =YEAR(E8) -> 2023 | E8: 44998 | F8: CUST007 | G8: Male | H8: 46 | I8: {=_xlfn.IFS(H8<30, "Young Adult", H8<50, "Adult", H8>=50, "Senior")} -> Adult | J8: Clothing | K8: 2 | L8: 25 | M8: =K8 * L8 -> 50 | N8: =M8 * $Q$3 -> 0.75 | O8: =M8 * $Q$4 -> 1 | R8: Female | S8: Male | T8: Average sales
A9: 8 | B9: =DAY(E9) -> 22 | C9: =MONTH(E9) -> 2 | D9: =YEAR(E9) -> 2023 | E9: 44979 | F9: CUST008 | G9: Male | H9: 30 | I9: {=_xlfn.IFS(H9<30, "Young Adult", H9<50, "Adult", H9>=50, "Senior")} -> Adult | J9: Electronics | K9: 4 | L9: 25 | M9: =K9 * L9 -> 100 | N9: =M9 * $Q$3 -> 1.5 | O9: =M9 * $Q$4 -> 2 | R9: =SUMIFS(K:K, G:G, "Female", J:J, "Beauty") -> 418 | S9: =SUMIFS(K:K,G:G, "Male", J:J, "Beauty") -> 353 | T9: =AVERAGE(M:M) -> 456
A10: 9 | B10: =DAY(E10) -> 13 | C10: =MONTH(E10) -> 12 | D10: =YEAR(E10) -> 2023 | E10: 45273 | F10: CUST009 | G10: Male | H10: 63 | I10: {=_xlfn.IFS(H10<30, "Young Adult", H10<50, "Adult", H10>=50, "Senior")} -> Senior | J10: Electronics | K10: 2 | L10: 300 | M10: =K10 * L10 -> 600 | N10: =M10 * $Q$3 -> 9 | O10: =M10 * $Q$4 -> 12 | P10: =SUM(N:N) -> 6840 | R10: =SUMIFS(K:K, G:G, "Female", J:J, "Electronics") -> 439 | S10: =SUMIFS(K:K,G:G, "Male",J:J, "Electronics") -> 410 | T10: =AVERAGEIF(J:J,P10,M:M) -> #DIV/0!
A11: 10 | B11: =DAY(E11) -> 7 | C11: =MONTH(E11) -> 10 | D11: =YEAR(E11) -> 2023 | E11: 45206 | F11: CUST010 | G11: Female | H11: 52 | I11: {=_xlfn.IFS(H11<30, "Young Adult", H11<50, "Adult", H11>=50, "Senior")} -> Senior | J11: Clothing | K11: 4 | L11: 50 | M11: =K11 * L11 -> 200 | N11: =M11 * $Q$3 -> 3 | O11: =M11 * $Q$4 -> 4 | P11: =AVERAGE(N:N) -> 6.84 | Q11: Total Sales | R11: =SUMIFS(K:K, G:G, "Female", J:J, "clothing") -> 441 | S11: =SUMIFS(K:K, G:G, "Male", J:J, "Clothing") -> 453 | T11: =AVERAGEIF(J:J,P11,M:M) -> #DIV/0!
A12: 11 | B12: =DAY(E12) -> 14 | C12: =MONTH(E12) -> 2 | D12: =YEAR(E12) -> 2023 | E12: 44971 | F12: CUST011 | G12: Male | H12: 23 | I12: {=_xlfn.IFS(H12<30, "Young Adult", H12<50, "Adult", H12>=50, "Senior")} -> Young Adult | J12: Clothing | K12: 2 | L12: 50 | M12: =K12 * L12 -> 100 | N12: =M12 * $Q$3 -> 1.5 | O12: =M12 * $Q$4 -> 2
A13: 12 | B13: =DAY(E13) -> 30 | C13: =MONTH(E13) -> 10 | D13: =YEAR(E13) -> 2023 | E13: 45229 | F13: CUST012 | G13: Male | H13: 35 | I13: {=_xlfn.IFS(H13<30, "Young Adult", H13<50, "Adult", H13>=50, "Senior")} -> Adult | J13: Beauty | K13: 3 | L13: 25 | M13: =K13 * L13 -> 75 | N13: =M13 * $Q$3 -> 1.125 | O13: =M13 * $Q$4 -> 1.5
A14: 13 | B14: =DAY(E14) -> 5 | C14: =MONTH(E14) -> 8 | D14: =YEAR(E14) -> 2023 | E14: 45143 | F14: CUST013 | G14: Male | H14: 22 | I14: {=_xlfn.IFS(H14<30, "Young Adult", H14<50, "Adult", H14>=50, "Senior")} -> Young Adult | J14: Electronics | K14: 3 | L14: 500 | M14: =K14 * L14 -> 1500 | N14: =M14 * $Q$3 -> 22.5 | O14: =M14 * $Q$4 -> 30 | P14: All products | Q14: =SUM(M:M) -> 456000
A15: 14 | B15: =DAY(E15) -> 17 | C15: =MONTH(E15) -> 1 | D15: =YEAR(E15) -> 2023 | E15: 44943 | F15: CUST014 | G15: Male | H15: 64 | I15: {=_xlfn.IFS(H15<30, "Young Adult", H15<50, "Adult", H15>=50, "Senior")} -> Senior | J15: Clothing | K15: 4 | L15: 30 | M15: =K15 * L15 -> 120 | N15: =M15 * $Q$3 -> 1.8 | O15: =M15 * $Q$4 -> 2.4
A16: 15 | B16: =DAY(E16) -> 16 | C16: =MONTH(E16) -> 1 | D16: =YEAR(E16) -> 2023 | E16: 44942 | F16: CUST015 | G16: Female | H16: 42 | I16: {=_xlfn.IFS(H16<30, "Young Adult", H16<50, "Adult", H16>=50, "Senior")} -> Adult | J16: Electronics | K16: 4 | L16: 500 | M16: =K16 * L16 -> 2000 | N16: =M16 * $Q$3 -> 30 | O16: =M16 * $Q$4 -> 40
A17: 16 | B17: =DAY(E17) -> 17 | C17: =MONTH(E17) -> 2 | D17: =YEAR(E17) -> 2023 | E17: 44974 | F17: CUST016 | G17: Male | H17: 19 | I17: {=_xlfn.IFS(H17<30, "Young Adult", H17<50, "Adult", H17>=50, "Senior")} -> Young Adult | J17: Clothing | K17: 3 | L17: 500 | M17: =K17 * L17 -> 1500 | N17: =M17 * $Q$3 -> 22.5 | O17: =M17 * $Q$4 -> 30 | P17: Clothing | Q17: =SUMIF(J:J, "Clothing", M:M) -> 155580
A18: 17 | B18: =DAY(E18) -> 22 | C18: =MONTH(E18) -> 4 | D18: =YEAR(E18) -> 2023 | E18: 45038 | F18: CUST017 | G18: Female | H18: 27 | I18: {=_xlfn.IFS(H18<30, "Young Adult", H18<50, "Adult", H18>=50, "Senior")} -> Young Adult | J18: Clothing | K18: 4 | L18: 25 | M18: =K18 * L18 -> 100 | N18: =M18 * $Q$3 -> 1.5 | O18: =M18 * $Q$4 -> 2
A19: 18 | B19: =DAY(E19) -> 30 | C19: =MONTH(E19) -> 4 | D19: =YEAR(E19) -> 2023 | E19: 45046 | F19: CUST018 | G19: Female | H19: 47 | I19: {=_xlfn.IFS(H19<30, "Young Adult", H19<50, "Adult", H19>=50, "Senior")} -> Adult | J19: Electronics | K19: 2 | L19: 25 | M19: =K19 * L19 -> 50 | N19: =M19 * $Q$3 -> 0.75 | O19: =M19 * $Q$4 -> 1
A20: 19 | B20: =DAY(E20) -> 16 | C20: =MONTH(E20) -> 9 | D20: =YEAR(E20) -> 2023 | E20: 45185 | F20: CUST019 | G20: Female | H20: 62 | I20: {=_xlfn.IFS(H20<30, "Young Adult", H20<50, "Adult", H20>=50, "Senior")} -> Senior | J20: Clothing | K20: 2 | L20: 25 | M20: =K20 * L20 -> 50 | N20: =M20 * $Q$3 -> 0.75 | O20: =M20 * $Q$4 -> 1
A21: 20 | B21: =DAY(E21) -> 5 | C21: =MONTH(E21) -> 11 | D21: =YEAR(E21) -> 2023 | E21: 45235 | F21: CUST020 | G21: Male | H21: 22 | I21: {=_xlfn.IFS(H21<30, "Young Adult", H21<50, "Adult", H21>=50, "Senior")} -> Young Adult | J21: Clothing | K21: 3 | L21: 300 | M21: =K21 * L21 -> 900 | N21: =M21 * $Q$3 -> 13.5 | O21: =M21 * $Q$4 -> 18
A22: 21 | B22: =DAY(E22) -> 14 | C22: =MONTH(E22) -> 1 | D22: =YEAR(E22) -> 2023 | E22: 44940 | F22: CUST021 | G22: Female | H22: 50 | I22: {=_xlfn.IFS(H22<30, "Young Adult", H22<50, "Adult", H22>=50, "Senior")} -> Senior | J22: Beauty | K22: 1 | L22: 500 | M22: =K22 * L22 -> 500 | N22: =M22 * $Q$3 -> 7.5 | O22: =M22 * $Q$4 -> 10
A23: 22 | B23: =DAY(E23) -> 15 | C23: =MONTH(E23) -> 10 | D23: =YEAR(E23) -> 2023 | E23: 45214 | F23: CUST022 | G23: Male | H23: 18 | I23: {=_xlfn.IFS(H23<30, "Young Adult", H23<50, "Adult", H23>=50, "Senior")} -> Young Adult | J23: Clothing | K23: 2 | L23: 50 | M23: =K23 * L23 -> 100 | N23: =M23 * $Q$3 -> 1.5 | O23: =M23 * $Q$4 -> 2
A24: 23 | B24: =DAY(E24) -> 12 | C24: =MONTH(E24) -> 4 | D24: =YEAR(E24) -> 2023 | E24: 45028 | F24: CUST023 | G24: Female | H24: 35 | I24: {=_xlfn.IFS(H24<30, "Young Adult", H24<50, "Adult", H24>=50, "Senior")} -> Adult | J24: Clothing | K24: 4 | L24: 30 | M24: =K24 * L24 -> 120 | N24: =M24 * $Q$3 -> 1.8 | O24: =M24 * $Q$4 -> 2.4
A25: 24 | B25: =DAY(E25) -> 29 | C25: =MONTH(E25) -> 11 | D25: =YEAR(E25) -> 2023 | E25: 45259 | F25: CUST024 | G25: Female | H25: 49 | I25: {=_xlfn.IFS(H25<30, "Young Adult", H25<50, "Adult", H25>=50, "Senior")} -> Adult | J25: Clothing | K25: 1 | L25: 300 | M25: =K25 * L25 -> 300 | N25: =M25 * $Q$3 -> 4.5 | O25: =M25 * $Q$4 -> 6
A26: 25 | B26: =DAY(E26) -> 26 | C26: =MONTH(E26) -> 12 | D26: =YEAR(E26) -> 2023 | E26: 45286 | F26: CUST025 | G26: Female | H26: 64 | I26: {=_xlfn.IFS(H26<30, "Young Adult", H26<50, "Adult", H26>=50, "Senior")} -> Senior | J26: Beauty | K26: 1 | L26: 50 | M26: =K26 * L26 -> 50 | N26: =M26 * $Q$3 -> 0.75 | O26: =M26 * $Q$4 -> 1
A27: 26 | B27: =DAY(E27) -> 7 | C27: =MONTH(E27) -> 10 | D27: =YEAR(E27) -> 2023 | E27: 45206 | F27: CUST026 | G27: Female | H27: 28 | I27: {=_xlfn.IFS(H27<30, "Young Adult", H27<50, "Adult", H27>=50, "Senior")} -> Young Adult | J27: Electronics | K27: 2 | L27: 500 | M27: =K27 * L27 -> 1000 | N27: =M27 * $Q$3 -> 15 | O27: =M27 * $Q$4 -> 20
A28: 27 | B28: =DAY(E28) -> 3 | C28: =MONTH(E28) -> 8 | D28: =YEAR(E28) -> 2023 | E28: 45141 | F28: CUST027 | G28: Female | H28: 38 | I28: {=_xlfn.IFS(H28<30, "Young Adult", H28<50, "Adult", H28>=50, "Senior")} -> Adult | J28: Beauty | K28: 2 | L28: 25 | M28: =K28 * L28 -> 50 | N28: =M28 * $Q$3 -> 0.75 | O28: =M28 * $Q$4 -> 1
A29: 28 | B29: =DAY(E29) -> 23 | C29: =MONTH(E29) -> 4 | D29: =YEAR(E29) -> 2023 | E29: 45039 | F29: CUST028 | G29: Female | H29: 43 | I29: {=_xlfn.IFS(H29<30, "Young Adult", H29<50, "Adult", H29>=50, "Senior")} -> Adult | J29: Beauty | K29: 1 | L29: 500 | M29: =K29 * L29 -> 500 | N29: =M29 * $Q$3 -> 7.5 | O29: =M29 * $Q$4 -> 10
... A32: 31 | B32: =DAY(E32) -> 23 | C32: =MONTH(E32) -> 5 | D32: =YEAR(E32) -> 2023 | E32: 45069 | F32: CUST031 | G32: Male | H32: 44 | I32: {=_xlfn.IFS(H32<30, "Young Adult", H32<50, "Adult", H32>=50, "Senior")} -> Adult | J32: Electronics | K32: 4 | L32: 300 | M32: =K32 * L32 -> 1200 | N32: =M32 * $Q$3 -> 18 | O32: =M32 * $Q$4 -> 24
A33: 32 | B33: =DAY(E33) -> 4 | C33: =MONTH(E33) -> 1 | D33: =YEAR(E33) -> 2023 | E33: 44930 | F33: CUST032 | G33: Male | H33: 30 | I33: {=_xlfn.IFS(H33<30, "Young Adult", H33<50, "Adult", H33>=50, "Senior")} -> Adult | J33: Beauty | K33: 3 | L33: 30 | M33: =K33 * L33 -> 90 | N33: =M33 * $Q$3 -> 1.35 | O33: =M33 * $Q$4 -> 1.8 | P33: Electronics | Q33: =SUMIF(J:J, "Electronics", M:M) -> 156905
A34: 33 | B34: =DAY(E34) -> 23 | C34: =MONTH(E34) -> 3 | D34: =YEAR(E34) -> 2023 | E34: 45008 | F34: CUST033 | G34: Female | H34: 50 | I34: {=_xlfn.IFS(H34<30, "Young Adult", H34<50, "Adult", H34>=50, "Senior")} -> Senior | J34: Electronics | K34: 2 | L34: 50 | M34: =K34 * L34 -> 100 | N34: =M34 * $Q$3 -> 1.5 | O34: =M34 * $Q$4 -> 2
A35: 34 | B35: =DAY(E35) -> 24 | C35: =MONTH(E35) -> 12 | D35: =YEAR(E35) -> 2023 | E35: 45284 | F35: CUST034 | G35: Female | H35: 51 | I35: {=_xlfn.IFS(H35<30, "Young Adult", H35<50, "Adult", H35>=50, "Senior")} -> Senior | J35: Clothing | K35: 3 | L35: 50 | M35: =K35 * L35 -> 150 | N35: =M35 * $Q$3 -> 2.25 | O35: =M35 * $Q$4 -> 3
A36: 35 | B36: =DAY(E36) -> 5 | C36: =MONTH(E36) -> 8 | D36: =YEAR(E36) -> 2023 | E36: 45143 | F36: CUST035 | G36: Female | H36: 58 | I36: {=_xlfn.IFS(H36<30, "Young Adult", H36<50, "Adult", H36>=50, "Senior")} -> Senior | J36: Beauty | K36: 3 | L36: 300 | M36: =K36 * L36 -> 900 | N36: =M36 * $Q$3 -> 13.5 | O36: =M36 * $Q$4 -> 18
A37: 36 | B37: =DAY(E37) -> 24 | C37: =MONTH(E37) -> 6 | D37: =YEAR(E37) -> 2023 | E37: 45101 | F37: CUST036 | G37: Male | H37: 52 | I37: {=_xlfn.IFS(H37<30, "Young Adult", H37<50, "Adult", H37>=50, "Senior")} -> Senior | J37: Beauty | K37: 3 | L37: 300 | M37: =K37 * L37 -> 900 | N37: =M37 * $Q$3 -> 13.5 | O37: =M37 * $Q$4 -> 18
A38: 37 | B38: =DAY(E38) -> 23 | C38: =MONTH(E38) -> 5 | D38: =YEAR(E38) -> 2023 | E38: 45069 | F38: CUST037 | G38: Female | H38: 18 | I38: {=_xlfn.IFS(H38<30, "Young Adult", H38<50, "Adult", H38>=50, "Senior")} -> Young Adult | J38: Beauty | K38: 3 | L38: 25 | M38: =K38 * L38 -> 75 | N38: =M38 * $Q$3 -> 1.125 | O38: =M38 * $Q$4 -> 1.5
A39: 38 | B39: =DAY(E39) -> 21 | C39: =MONTH(E39) -> 3 | D39: =YEAR(E39) -> 2023 | E39: 45006 | F39: CUST038 | G39: Male | H39: 38 | I39: {=_xlfn.IFS(H39<30, "Young Adult", H39<50, "Adult", H39>=50, "Senior")} -> Adult | J39: Beauty | K39: 4 | L39: 50 | M39: =K39 * L39 -> 200 | N39: =M39 * $Q$3 -> 3 | O39: =M39 * $Q$4 -> 4
A40: 39 | B40: =DAY(E40) -> 21 | C40: =MONTH(E40) -> 4 | D40: =YEAR(E40) -> 2023 | E40: 45037 | F40: CUST039 | G40: Male | H40: 23 | I40: {=_xlfn.IFS(H40<30, "Young Adult", H40<50, "Adult", H40>=50, "Senior")} -> Young Adult | J40: Clothing | K40: 4 | L40: 30 | M40: =K40 * L40 -> 120 | N40: =M40 * $Q$3 -> 1.8 | O40: =M40 * $Q$4 -> 2.4
A41: 40 | B41: =DAY(E41) -> 22 | C41: =MONTH(E41) -> 6 | D41: =YEAR(E41) -> 2023 | E41: 45099 | F41: CUST040 | G41: Male | H41: 45 | I41: {=_xlfn.IFS(H41<30, "Young Adult", H41<50, "Adult", H41>=50, "Senior")} -> Adult | J41: Beauty | K41: 1 | L41: 50 | M41: =K41 * L41 -> 50 | N41: =M41 * $Q$3 -> 0.75 | O41: =M41 * $Q$4 -> 1
A42: 41 | B42: =DAY(E42) -> 22 | C42: =MONTH(E42) -> 2 | D42: =YEAR(E42) -> 2023 | E42: 44979 | F42: CUST041 | G42: Male | H42: 34 | I42: {=_xlfn.IFS(H42<30, "Young Adult", H42<50, "Adult", H42>=50, "Senior")} -> Adult | J42: Clothing | K42: 2 | L42: 25 | M42: =K42 * L42 -> 50 | N42: =M42 * $Q$3 -> 0.75 | O42: =M42 * $Q$4 -> 1
...

Sheet Transactions
A1: Transaction ID | B1: Total Sales | C1: Product category | D1: concatenate
A2: 10 | B2: =VLOOKUP(A2,retail_sales_dataset!$1:$1048576, 13, FALSE) -> 200 | C2: =VLOOKUP(A2,retail_sales_dataset!$1:$1048576, 10,FALSE) -> Clothing | D2: =CONCATENATE(B2, "", C2) -> 200Clothing
A3: 15 | B3: =VLOOKUP(A3,retail_sales_dataset!$1:$1048576, 13, FALSE) -> 2000 | C3: =VLOOKUP(A3,retail_sales_dataset!$1:$1048576, 10,FALSE) -> Electronics | D3: =CONCATENATE(B3, "", C3) -> 2000Electronics
A4: 25 | B4: =VLOOKUP(A4,retail_sales_dataset!$1:$1048576, 13, FALSE) -> 50 | C4: =VLOOKUP(A4,retail_sales_dataset!$1:$1048576, 10,FALSE) -> Beauty | D4: =CONCATENATE(B4, "", C4) -> 50Beauty
A5: 30 | B5: =VLOOKUP(A5,retail_sales_dataset!$1:$1048576, 13, FALSE) -> 900 | C5: =VLOOKUP(A5,retail_sales_dataset!$1:$1048576, 10,FALSE) -> Beauty | D5: =CONCATENATE(B5, "", C5) -> 900Beauty
A6: 54 | B6: =VLOOKUP(A6,retail_sales_dataset!$1:$1048576, 13, FALSE) -> 1500 | C6: =VLOOKUP(A6,retail_sales_dataset!$1:$1048576, 10,FALSE) -> Electronics | D6: =CONCATENATE(B6, "", C6) -> 1500Electronics
A7: 55 | B7: =VLOOKUP(A7,retail_sales_dataset!$1:$1048576, 13, FALSE) -> 120 | C7: =VLOOKUP(A7,retail_sales_dataset!$1:$1048576, 10,FALSE) -> Beauty | D7: =CONCATENATE(B7, "", C7) -> 120Beauty
A8: 67 | B8: =VLOOKUP(A8,retail_sales_dataset!$1:$1048576, 13, FALSE) -> 1200 | C8: =VLOOKUP(A8,retail_sales_dataset!$1:$1048576, 10,FALSE) -> Beauty | D8: =CONCATENATE(B8, "", C8) -> 1200Beauty
A9: 89 | B9: =VLOOKUP(A9,retail_sales_dataset!$1:$1048576, 13, FALSE) -> 2000 | C9: =VLOOKUP(A9,retail_sales_dataset!$1:$1048576, 10,FALSE) -> Electronics | D9: =CONCATENATE(B9, "", C9) -> 2000Electronics
A10: 100 | B10: =VLOOKUP(A10,retail_sales_dataset!$1:$1048576, 13, FALSE) -> 30 | C10: =VLOOKUP(A10,retail_sales_dataset!$1:$1048576, 10,FALSE) -> Electronics | D10: =CONCATENATE(B10, "", C10) -> 30Electronics
B11: count: number of rows contain number
A12: =COUNTA(A2:A10) -> 9 | B12: =COUNT(B2:B10) -> 9 | C12: =COUNT(C2) -> 0

Sheet Day 2 Task 2
A1: Student name | B1: English | C1: Mathematics | D1: Science | E1: Average | F1: Highest score
A2: Ted | B2: 80 | C2: 75 | D2: 90 | E2: =AVERAGE(B2:D2) -> 81.666667 | F2: =MAX(B2:D2) -> 90
A3: Linda | B3: 90 | C3: 50 | D3: 70 | E3: =AVERAGE(B3:D3) -> 70 | F3: =MAX(B3:D3) -> 90
A4: Carol | B4: 75 | C4: 85 | D4: 85 | E4: =AVERAGE(B4:D4) -> 81.666667 | F4: =MAX(B4:D4) -> 85
A5: Khan | B5: 85 | C5: 75 | D5: 80 | E5: =AVERAGE(B5:D5) -> 80 | F5: =MAX(B5:D5) -> 85
A6: Harry | B6: 80 | C6: 70 | D6: 80 | E6: =AVERAGE(B6:D6) -> 76.666667 | F6: =MAX(B6:D6) -> 80
A7: Sarah | B7: 80 | C7: 70 | D7: 80 | E7: =AVERAGE(B7:D7) -> 76.666667 | F7: =MAX(B7:D7) -> 80
A8: John | B8: 65 | C8: 80 | D8: 70 | E8: =AVERAGE(B8:D8) -> 71.666667 | F8: =MAX(B8:D8) -> 80
A9: Edward | B9: 55 | C9: 80 | D9: 60 | E9: =AVERAGE(B9:D9) -> 65 | F9: =MAX(B9:D9) -> 80
A10: Mary | B10: 55 | C10: 70 | D10: 65 | E10: =AVERAGE(B10:D10) -> 63.333333 | F10: =MAX(B10:D10) -> 70
A11: Thomas | B11: 55 | C11: 30 | D11: 65 | E11: =AVERAGE(B11:D11) -> 50 | F11: =MAX(B11:D11) -> 65
A14: Task
A15: 1) Apply filter and sorting to show the best students in each subject.
A16: 2) Calculate the average for all students and fill into Column E. (Use formula)
A17: 3) Using the =MAX fucntion, tell me what the students highest score was in column F.
A18: 4) Apply filter and sorting to show the best student in this classroom by average.
A19: 5) Apply filter and sorting to show the best student in this classroom by highest score.
A20: 6) Use conditional formatting to clearly identify the highest and lowest average scores
